<?xml version="1.0" ?>
<robot xmlns:xacro="http://www.ros.org/wiki/xacro">
  <xacro:macro name="motoman_arm" params="name prefix parent *origin reflect">
    <link name="${prefix}link_1_s">
      <visual>
        <origin rpy="0 0 0" xyz="0 0 0"/>
        <geometry>
          <mesh filename="package://motoman_sda10f_support/meshes/sda10f/visual/motoman_axis_s.stl"/>
        </geometry>
        <material name="blue">
          <color rgba="0.8 0.8 0.8 1"/>
        </material>
      </visual>
      <collision>
        <origin rpy="0 0 0" xyz="0 0 0"/>
        <geometry>
          <mesh filename="package://motoman_sda10f_support/meshes/sda10f/collision/motoman_axis_s.stl" />
        </geometry>
        <material name="yellow"/>
      </collision>
      <inertial>
        <origin xyz="0 0 -0.125" rpy="0 0 0" />
        <mass value="7" />
        <inertia  ixx="0.0457840833333" ixy="0" ixz="0"
                  iyy="0.0457840833333" iyz="0"
                  izz="0.0186515" />
      </inertial>
    </link>
    <link name="${prefix}link_2_l">
      <visual>
        <origin rpy="0 0 0" xyz="0 0 0"/>
        <geometry>
          <mesh filename="package://motoman_sda10f_support/meshes/sda10f/visual/motoman_axis_l.stl"/>
        </geometry>
        <material name="silver"/>
      </visual>
      <collision>
        <origin rpy="0 0 0" xyz="0 0 0"/>
        <geometry>
          <mesh filename="package://motoman_sda10f_support/meshes/sda10f/collision/motoman_axis_l.stl"/>
        </geometry>
        <material name="yellow"/>
      </collision>
      <inertial>
        <origin xyz="0 0 -0.0365" rpy="0 0 0" />
        <mass value="6" />
        <inertia  ixx="0.026102" ixy="0" ixz="0"
                  iyy="0.026102" iyz="0"
                  izz="0.046875" />
      </inertial>
    </link>
    <link name="${prefix}link_3_e">
      <visual>
        <origin rpy="0 0 0" xyz="0 0 0"/>
        <geometry>
          <mesh filename="package://motoman_sda10f_support/meshes/sda10f/visual/motoman_axis_e.stl"/>
        </geometry>
        <material name="blue"/>
      </visual>
      <collision>
        <origin rpy="0 0 0" xyz="0 0 0"/>
        <geometry>
          <mesh filename="package://motoman_sda10f_support/meshes/sda10f/collision/motoman_axis_e.stl"/>
        </geometry>
        <material name="yellow"/>
      </collision>
      <inertial>
        <origin xyz="0 0 -0.125" rpy="0 0 0" />
        <mass value="5" />
        <inertia  ixx="0.0327029166667" ixy="0" ixz="0"
                  iyy="0.0327029166667" iyz="0"
                  izz="0.0133225" />
      </inertial>
    </link>
    <link name="${prefix}link_4_u">
      <visual>
        <origin rpy="0 0 0" xyz="0 0 0"/>
        <geometry>
          <mesh filename="package://motoman_sda10f_support/meshes/sda10f/visual/motoman_axis_u.stl"/>
        </geometry>
        <material name="silver"/>
      </visual>
      <collision>
        <origin rpy="0 0 0" xyz="0 0 0"/>
        <geometry>
          <mesh filename="package://motoman_sda10f_support/meshes/sda10f/collision/motoman_axis_u.stl"/>
        </geometry>
        <material name="yellow"/>
      </collision>
      <inertial>
        <origin xyz="0 0 -0.0365" rpy="0 0 0" />
        <mass value="5" />
        <inertia  ixx="0.0217516666667" ixy="0" ixz="0"
                  iyy="0.0217516666667" iyz="0"
                  izz="0.0390625" />
      </inertial>
    </link>
    <link name="${prefix}link_5_r">
      <visual>
        <origin rpy="0 0 0" xyz="0 0 0"/>
        <geometry>
          <mesh filename="package://motoman_sda10f_support/meshes/sda10f/visual/motoman_axis_r.stl"/>
        </geometry>
        <material name="blue"/>
      </visual>
      <collision>
        <origin rpy="0 0 0" xyz="0 0 0"/>
        <geometry>
          <mesh filename="package://motoman_sda10f_support/meshes/sda10f/collision/motoman_axis_r.stl"/>
        </geometry>
        <material name="yellow"/>
      </collision>
      <inertial>
        <origin xyz="0 0 -0.125" rpy="0 0 0" />
        <mass value="4" />
        <inertia  ixx="0.0261623333333" ixy="0" ixz="0"
                  iyy="0.0261623333333" iyz="0"
                  izz="0.010658" />
      </inertial>
    </link>
    <link name="${prefix}link_6_b">
      <visual>
        <origin rpy="0 0 0" xyz="0 0 0"/>
        <geometry>
          <mesh filename="package://motoman_sda10f_support/meshes/sda10f/visual/motoman_axis_b.stl"/>
        </geometry>
        <material name="silver"/>
      </visual>
      <collision>
        <origin rpy="0 0 0" xyz="0 0 0"/>
        <geometry>
          <mesh filename="package://motoman_sda10f_support/meshes/sda10f/collision/motoman_axis_b.stl"/>
        </geometry>
        <material name="yellow"/>
      </collision>
      <inertial>
        <origin xyz="0 0 -0.0365" rpy="0 0 0" />
        <mass value="4" />
        <inertia  ixx="0.0174013333333" ixy="0" ixz="0"
                  iyy="0.0174013333333" iyz="0"
                  izz="0.03125" />
      </inertial>
    </link>
    <link name="${prefix}link_7_t">
      <visual>
        <geometry>
          <mesh filename="package://motoman_sda10f_support/meshes/sda10f/visual/motoman_axis_t.stl" />
        </geometry>
        <material name="blue"/>
      </visual>
      <collision>
        <geometry>
          <mesh filename="package://motoman_sda10f_support/meshes/sda10f/collision/motoman_axis_t.stl" />
        </geometry>
        <material name="yellow"/>
      </collision>
      <inertial>
        <origin xyz="0 0 -0.0075" rpy="0 0 0" />
        <mass value="0.5" />
        <inertia  ixx="0.000209375" ixy="0" ixz="0"
                  iyy="0.000209375" iyz="0"
                  izz="0.0004" />
      </inertial>
    </link>
    <link name="${prefix}link_tool0" />

    <joint name="${prefix}joint_1_s" type="revolute">
      <parent link="${parent}"/>
      <child link="${prefix}link_1_s"/>
      <origin xyz="0.09996 ${reflect*0.0275} 0.32214" rpy="1.57 0 ${(reflect-1)*1.57}"/>
      <axis xyz="0 0 ${-reflect}" />
      <limit lower="-3.13" upper="3.13" effort="0" velocity="2.95" />
      <dynamics damping="0.2" friction="0" />
    </joint>
    <joint name="${prefix}joint_2_l" type="revolute">
      <parent link="${prefix}link_1_s"/>
      <child link="${prefix}link_2_l"/>
      <origin xyz="0 0.0577 -0.2255" rpy="-1.57 0 0"/>
      <axis xyz="0 0 ${-reflect}" />
      <limit lower="-1.90" upper="1.90" effort="0" velocity="2.95" />
      <dynamics damping="0.2" friction="0" />
    </joint>
    <joint name="${prefix}joint_3_e" type="revolute">
      <parent link="${prefix}link_2_l"/>
      <child link="${prefix}link_3_e"/>
      <origin xyz="0 0.1690 -0.0454" rpy="1.57 0 0"/>
      <axis xyz="0 0 ${-reflect}" />
      <limit lower="-2.95" upper="2.95" effort="0" velocity="2.95" />
      <dynamics damping="0.2" friction="0" />
    </joint>
    <joint name="${prefix}joint_4_u" type="revolute">
      <parent link="${prefix}link_3_e"/>
      <child link="${prefix}link_4_u"/>
      <origin xyz="0 -0.0085 -0.181" rpy="-1.57 0 0"/>
      <axis xyz="0 0 ${reflect}" />
      <limit lower="-2.36" upper="2.36" effort="0" velocity="2.95" />
      <dynamics damping="0.2" friction="0" />
    </joint>
    <joint name="${prefix}joint_5_r" type="revolute">
      <parent link="${prefix}link_4_u"/>
      <child link="${prefix}link_5_r"/>
      <origin xyz="0 0.1936 0.0155" rpy="1.57 0 0"/>
      <axis xyz="0 0 ${reflect}" />
      <limit lower="-3.13" upper="3.13" effort="0" velocity="3.48" />
      <dynamics damping="0.2" friction="0" />
    </joint>
    <joint name="${prefix}joint_6_b" type="revolute">
      <parent link="${prefix}link_5_r"/>
      <child link="${prefix}link_6_b"/>
      <origin xyz="0 0.0080 -0.155" rpy="-1.57 0 0"/>
      <axis xyz="0 0 ${reflect}" />
      <limit lower="-1.90" upper="1.90" effort="0" velocity="3.48" />
      <dynamics damping="0.2" friction="0" />
    </joint>
    <joint name="${prefix}joint_7_t" type="revolute">
      <parent link="${prefix}link_6_b"/>
      <child link="${prefix}link_7_t"/>
      <origin xyz="0 0.168 -0.015" rpy="1.57 0 0"/>
      <axis xyz="0 0 ${-reflect}" />
      <limit lower="-3.13" upper="3.13" effort="0" velocity="6.97" />
      <dynamics damping="0.2" friction="0" />
    </joint>
    <joint name="${prefix}joint_tool0" type="fixed" >
      <origin xyz="0 0 0.0" rpy="0 0 -3.13"/>
      <parent link="${prefix}link_7_t" />
      <child link="${prefix}link_tool0" />
      <dynamics damping="0.2" friction="0" />
    </joint>
    <!-- Transmissions -->
    <transmission name="${prefix}joint_1_s">
      <type>transmission_interface/SimpleTransmission</type>
      <joint name="${prefix}joint_1_s">
        <hardwareInterface>
          hardware_interface/PositionJointInterface
        </hardwareInterface>
      </joint>
      <actuator name="${prefix}motor_joint_1_s">
        <mechanicalReduction>1</mechanicalReduction>
      </actuator>
    </transmission>
    <transmission name="${prefix}joint_2_l">
      <type>transmission_interface/SimpleTransmission</type>
      <joint name="${prefix}joint_2_l">
        <hardwareInterface>
          hardware_interface/PositionJointInterface
        </hardwareInterface>
      </joint>
      <actuator name="${prefix}motor_joint_2_l">
        <mechanicalReduction>1</mechanicalReduction>
      </actuator>
    </transmission>
    <transmission name="${prefix}joint_3_e">
      <type>transmission_interface/SimpleTransmission</type>
      <joint name="${prefix}joint_3_e">
        <hardwareInterface>
          hardware_interface/PositionJointInterface
        </hardwareInterface>
      </joint>
      <actuator name="${prefix}motor_joint_3_e">
        <mechanicalReduction>1</mechanicalReduction>
      </actuator>
    </transmission>
    <transmission name="${prefix}joint_4_u">
      <type>transmission_interface/SimpleTransmission</type>
      <joint name="${prefix}joint_4_u">
        <hardwareInterface>
          hardware_interface/PositionJointInterface
        </hardwareInterface>
      </joint>
      <actuator name="${prefix}motor_joint_4_u_">
        <mechanicalReduction>1</mechanicalReduction>
      </actuator>
    </transmission>
    <transmission name="${prefix}joint_5_r">
      <type>transmission_interface/SimpleTransmission</type>
      <joint name="${prefix}joint_5_r">
        <hardwareInterface>
          hardware_interface/PositionJointInterface
        </hardwareInterface>
      </joint>
      <actuator name="${prefix}motor_joint_5_r">
        <mechanicalReduction>1</mechanicalReduction>
      </actuator>
    </transmission>
    <transmission name="${prefix}joint_6_b">
      <type>transmission_interface/SimpleTransmission</type>
      <joint name="${prefix}joint_6_b">
        <hardwareInterface>
          hardware_interface/PositionJointInterface
        </hardwareInterface>
      </joint>
      <actuator name="${prefix}motor_joint_6_b">
        <mechanicalReduction>1</mechanicalReduction>
      </actuator>
    </transmission>
    <transmission name="${prefix}joint_7_t">
      <type>transmission_interface/SimpleTransmission</type>
      <joint name="${prefix}joint_7_t">
        <hardwareInterface>
          hardware_interface/PositionJointInterface
        </hardwareInterface>
      </joint>
      <actuator name="${prefix}motor_joint_7_t">
        <mechanicalReduction>1</mechanicalReduction>
      </actuator>
    </transmission>
    <!-- Gazebo -->
    <gazebo reference="${prefix}link_1_s">
      <mu1>0.9</mu1>
      <mu2>0.9</mu2>
      <selfCollide>true</selfCollide>
      <material>Gazebo/Blue</material>
      <collision>
        <surface>
          <contact>
            <!-- Enable collitions with everything -->
            <collide_bitmask>0x10001</collide_bitmask>
          </contact>
        </surface>
      </collision>
    </gazebo>
    <gazebo reference="${prefix}link_2_l">
      <mu1>0.9</mu1>
      <mu2>0.9</mu2>
      <selfCollide>true</selfCollide>
      <material>Gazebo/White</material>
      <collision>
        <surface>
          <contact>
            <!-- Enable collitions with everything -->
            <collide_bitmask>0x10001</collide_bitmask>
          </contact>
        </surface>
      </collision>
    </gazebo>
    <gazebo reference="${prefix}link_3_e">
      <mu1>0.9</mu1>
      <mu2>0.9</mu2>
      <selfCollide>true</selfCollide>
      <material>Gazebo/Blue</material>
      <collision>
        <surface>
          <contact>
            <!-- Enable collitions with everything -->
            <collide_bitmask>0x10001</collide_bitmask>
          </contact>
        </surface>
      </collision>
    </gazebo>
    <gazebo reference="${prefix}link_4_u">
      <mu1>0.9</mu1>
      <mu2>0.9</mu2>
      <selfCollide>true</selfCollide>
      <material>Gazebo/White</material>
      <collision>
        <surface>
          <contact>
            <!-- Enable collitions with everything -->
            <collide_bitmask>0x10001</collide_bitmask>
          </contact>
        </surface>
      </collision>
    </gazebo>
    <gazebo reference="${prefix}link_5_r">
      <mu1>0.9</mu1>
      <mu2>0.9</mu2>
      <selfCollide>true</selfCollide>
      <material>Gazebo/Blue</material>
      <collision>
        <surface>
          <contact>
            <!-- Enable collitions with everything -->
            <collide_bitmask>0x10001</collide_bitmask>
          </contact>
        </surface>
      </collision>
    </gazebo>
    <gazebo reference="${prefix}link_6_b">
      <mu1>0.9</mu1>
      <mu2>0.9</mu2>
      <selfCollide>true</selfCollide>
      <material>Gazebo/White</material>
      <collision>
        <surface>
          <contact>
            <!-- Enable collitions with everything -->
            <collide_bitmask>0x10001</collide_bitmask>
          </contact>
        </surface>
      </collision>
    </gazebo>
    <gazebo reference="${prefix}link_7_t">
      <mu1>0.9</mu1>
      <mu2>0.9</mu2>
      <selfCollide>true</selfCollide>
      <material>Gazebo/Blue</material>
      <collision>
        <surface>
          <contact>
            <!-- Enable collitions with everything -->
            <collide_bitmask>0x10001</collide_bitmask>
          </contact>
        </surface>
      </collision>
    </gazebo>
  </xacro:macro>
</robot>
