<?xml version="1.0" ?>
<robot xmlns:xacro="http://www.ros.org/wiki/xacro">
  <xacro:macro name="torso" params="name prefix">
    <!-- link list -->
    <link name="${prefix}base_link">
      <visual>
        <geometry>
          <mesh filename="package://motoman_sda10f_support/meshes/sda10f/visual/motoman_base.stl" />
        </geometry>
        <material name="blue">
          <color rgba="0 0 1 1"/>
        </material>
      </visual>
      <collision>
        <geometry>
          <mesh filename="package://motoman_sda10f_support/meshes/sda10f/collision/motoman_base.stl" />
        </geometry>
        <material name="yellow">
          <color rgba="0 1 1 1"/>
        </material>
      </collision>
      <inertial>
        <origin xyz="0 0 0.43" rpy="0 0 0" />
        <mass value="100" />
        <inertia  ixx="7.16333333333" ixy="0" ixz="0"
                  iyy="7.16333333333" iyz="0"
                  izz="2" />
      </inertial>
    </link>
    <link name="${prefix}link_b1">
      <visual>
        <origin rpy="0 0 0" xyz="0 0 0"/>
        <geometry>
          <mesh filename="package://motoman_sda10f_support/meshes/sda10f/visual/motoman_axis_b1.stl"/>
        </geometry>
        <material name="silver">
          <color rgba="0.8 0.8 0.8 1"/>
        </material>
      </visual>
      <collision>
        <origin rpy="0 0 0" xyz="0 0 0"/>
        <geometry>
          <mesh filename="package://motoman_sda10f_support/meshes/sda10f/collision/motoman_axis_b1.stl" />
        </geometry>
        <material name="yellow"/>
      </collision>
      <inertial>
        <origin xyz="0 0 0.247" rpy="0 0 0" />
        <mass value="25" />
        <inertia  ixx="0.649033333333" ixy="0" ixz="0"
                  iyy="0.649033333333" iyz="0"
                  izz="0.28125" />
      </inertial>
    </link>
    <!-- Joints -->
    <joint name="${prefix}joint_b1" type="revolute">
      <parent link="${prefix}base_link"/>
      <child link="${prefix}link_b1"/>
      <origin xyz="0.09257 0 0.8835" rpy="0 0 0"/>
      <axis xyz="0 0 1" />
      <limit lower="-2.9570" upper="2.9570" effort="100" velocity="2.26" />
      <dynamics damping="0.2" friction="0" />
    </joint>
    <!-- Transmissions -->
    <transmission name="${prefix}joint_b1">
      <type>transmission_interface/SimpleTransmission</type>
      <joint name="${prefix}joint_b1">
        <hardwareInterface>
          hardware_interface/PositionJointInterface
        </hardwareInterface>
      </joint>
      <actuator name="${prefix}joint_b1_motor">
        <mechanicalReduction>1</mechanicalReduction>
      </actuator>
    </transmission>
    <!-- Gazebo -->
    <gazebo reference="${prefix}base_link">
      <mu1>0.9</mu1>
      <mu2>0.9</mu2>
      <selfCollide>true</selfCollide>
      <material>Gazebo/Blue</material>
      <collision>
        <surface>
          <contact>
            <!-- Disable collisions with the ground -->
            <collide_bitmask>0x10000</collide_bitmask>
          </contact>
        </surface>
      </collision>
    </gazebo>
    <gazebo reference="${prefix}link_b1">
      <mu1>0.9</mu1>
      <mu2>0.9</mu2>
      <selfCollide>true</selfCollide>
      <material>Gazebo/White</material>
      <collision>
        <surface>
          <contact>
            <!-- Enable collitions with everything -->
            <collide_bitmask>0x10001</collide_bitmask>
          </contact>
        </surface>
      </collision>
    </gazebo>
  </xacro:macro>
</robot>
